2023-07-31 15:16:25,962 | main_logger | MainProcess  |        <module>               | INFO  | Master execution started
2023-07-31 15:16:25,962 | main_logger | MainProcess  |        execute_pipeline_download | INFO  | calling the create_folder_structure function
2023-07-31 15:16:25,962 | main_logger | MainProcess  |        execute_pipeline_download | INFO  | calling the common_files_downloads function
2023-07-31 15:16:27,204 | main_logger | MainProcess  |        execute_pipeline_download | INFO  | calling the orchestrate_calling function
2023-07-31 15:16:27,206 | main_logger | MainProcess  |        task_orc_execution     | INFO  | execution at task level
2023-07-31 15:16:29,866 | main_logger | MainProcess  |        send_mail              | INFO  | mail sent
2023-07-31 15:16:35,541 | main_logger | MainProcess  |        task_orc_execution     | ERROR | error in orchestrate_task_calling local variable 'json_data' referenced before assignment.
Traceback (most recent call last):
  File "/home/nandishms/test//src/scripts/engine_main/engine_code.py", line 269, in engine_main
    json_data = task_json_read(paths_data,task_id,prj_nm)
  File "/home/nandishms/test//src/scripts/engine_main/engine_code.py", line 91, in task_json_read
    raise error
  File "/home/nandishms/test//src/scripts/engine_main/engine_code.py", line 83, in task_json_read
    with open(r""+os.path.expanduser(paths_data["folder_path"])+paths_data["Program"]+prj_nm+\
KeyError: 'Program'

During handling of the above exception, another exception occurred:

Traceback (most recent call last):
  File "/home/nandishms/test/src/scripts/orchestration/orchestrate.py", line 608, in task_orc_execution
    execute_job(prj_nm,paths_data,task_nm,run_id,file_path,iter_value)
  File "/home/nandishms/test/src/scripts/orchestration/orchestrate.py", line 38, in execute_job
    raise error
  File "/home/nandishms/test/src/scripts/orchestration/orchestrate.py", line 35, in execute_job
    download.execute_engine(prj_nm,task_id,paths_data,run_id,file_path,iter_value)
  File "/home/nandishms/test/download.py", line 242, in execute_engine
    raise error
  File "/home/nandishms/test/download.py", line 238, in execute_engine
    engine_code.engine_main(prj_nm,task_name,config_path,run_id,file_path,iter_value)
  File "/home/nandishms/test//src/scripts/engine_main/engine_code.py", line 424, in engine_main
    audit(json_data, task_id,run_id,'STATUS','FAILED',iter_value)
UnboundLocalError: local variable 'json_data' referenced before assignment
2023-07-31 15:16:35,543 | main_logger | MainProcess  |        get_ind_task_status    | INFO  | rest_api_test task is Start
2023-07-31 15:16:35,543 | main_logger | MainProcess  |        task_orc_execution     | INFO  | Task rest_api_test Execution failed.
2023-07-31 15:16:38,641 | main_logger | MainProcess  |        send_mail              | INFO  | mail sent
