2023-07-31 19:02:06,931 | task_logger | MainProcess  |        execute_engine         | INFO  | entered into execute_engine
2023-07-31 19:02:06,932 | task_logger | MainProcess  |        execute_engine         | INFO  | calling the task_json_download function
2023-07-31 19:02:07,973 | task_logger | MainProcess  |        download_task_files    | INFO  | entered into downloading task related files
2023-07-31 19:02:12,237 | task_logger | MainProcess  |        execute_engine         | INFO  | #####################################################
2023-07-31 19:02:12,237 | task_logger | MainProcess  |        execute_engine         | INFO  | calling the engine_main
2023-07-31 19:02:12,237 | task_logger | MainProcess  |        engine_main            | INFO  | entered into engine_main
2023-07-31 19:02:12,237 | task_logger | MainProcess  |        task_json_read         | INFO  | reading TASK JSON data started rest_api_test
2023-07-31 19:02:12,238 | task_logger | MainProcess  |        task_json_read         | INFO  | reading TASK JSON data completed
2023-07-31 19:02:12,265 | task_logger | MainProcess  |        audit                  | INFO  | audit status code:200
2023-07-31 19:02:12,266 | task_logger | MainProcess  |        checks_mapping_read    | INFO  | reading checks mapping json data started
2023-07-31 19:02:12,266 | task_logger | MainProcess  |        checks_mapping_read    | INFO  | reading checks mapping data completed
2023-07-31 19:02:13,470 | task_logger | MainProcess  |        begin_transaction      | INFO  | =================================================================
2023-07-31 19:02:13,471 | task_logger | MainProcess  |        begin_transaction      | INFO  | Transaction Started
2023-07-31 19:02:13,471 | task_logger | MainProcess  |        read_write_imports     | INFO  | read imports started
2023-07-31 19:02:13,471 | task_logger | MainProcess  |        read_write_imports     | INFO  | write imports started
2023-07-31 19:02:13,474 | task_logger | MainProcess  |        read                   | INFO  | timeouttttttttttttttttttt 100
2023-07-31 19:02:13,474 | task_logger | MainProcess  |        read                   | INFO  | urllllllllllll https://gorest.co.in/public/v2/users/2341/posts?page=1&per_page=10
2023-07-31 19:02:13,911 | task_logger | MainProcess  |        read                   | INFO  | URL specified in the config json is: https://gorest.co.in/public/v2...
2023-07-31 19:02:13,914 | task_logger | MainProcess  |        read                   | INFO  | number of records present in https://gorest.co.in/public/v2... is: 0
2023-07-31 19:02:13,942 | task_logger | MainProcess  |        audit                  | INFO  | audit status code:200
2023-07-31 19:02:13,943 | task_logger | MainProcess  |        write                  | INFO  | ingest data to mysql db initiated
2023-07-31 19:02:14,027 | task_logger | MainProcess  |        create                 | INFO  | rest_api_data19 does not exists so creating a new table
2023-07-31 19:02:14,027 | task_logger | MainProcess  |        insert_data            | INFO  | data ingesting with out audit columns
2023-07-31 19:02:14,031 | task_logger | MainProcess  |        insert_data            | INFO  | error occured in insert_data function (pymysql.err.ProgrammingError) (1064, "You have an error in your SQL syntax; check the manual that corresponds to your MySQL server version for the right syntax to use near ')' at line 2")
[SQL: 
CREATE TABLE rest_api_data19 (
)

]
(Background on this error at: https://sqlalche.me/e/20/f405)
2023-07-31 19:02:14,049 | task_logger | MainProcess  |        audit                  | INFO  | audit status code:200
2023-07-31 19:02:14,050 | task_logger | MainProcess  |        write                  | ERROR | write() is (pymysql.err.ProgrammingError) (1064, "You have an error in your SQL syntax; check the manual that corresponds to your MySQL server version for the right syntax to use near ')' at line 2")
[SQL: 
CREATE TABLE rest_api_data19 (
)

]
(Background on this error at: https://sqlalche.me/e/20/f405)
Traceback (most recent call last):
  File "/home/nandishms/.local/lib/python3.10/site-packages/sqlalchemy/engine/base.py", line 1965, in _exec_single_context
    self.dialect.do_execute(
  File "/home/nandishms/.local/lib/python3.10/site-packages/sqlalchemy/engine/default.py", line 921, in do_execute
    cursor.execute(statement, parameters)
  File "/home/nandishms/.local/lib/python3.10/site-packages/pymysql/cursors.py", line 153, in execute
    result = self._query(query)
  File "/home/nandishms/.local/lib/python3.10/site-packages/pymysql/cursors.py", line 322, in _query
    conn.query(q)
  File "/home/nandishms/.local/lib/python3.10/site-packages/pymysql/connections.py", line 558, in query
    self._affected_rows = self._read_query_result(unbuffered=unbuffered)
  File "/home/nandishms/.local/lib/python3.10/site-packages/pymysql/connections.py", line 822, in _read_query_result
    result.read()
  File "/home/nandishms/.local/lib/python3.10/site-packages/pymysql/connections.py", line 1200, in read
    first_packet = self.connection._read_packet()
  File "/home/nandishms/.local/lib/python3.10/site-packages/pymysql/connections.py", line 772, in _read_packet
    packet.raise_for_error()
  File "/home/nandishms/.local/lib/python3.10/site-packages/pymysql/protocol.py", line 221, in raise_for_error
    err.raise_mysql_exception(self._data)
  File "/home/nandishms/.local/lib/python3.10/site-packages/pymysql/err.py", line 143, in raise_mysql_exception
    raise errorclass(errno, errval)
pymysql.err.ProgrammingError: (1064, "You have an error in your SQL syntax; check the manual that corresponds to your MySQL server version for the right syntax to use near ')' at line 2")

The above exception was the direct cause of the following exception:

Traceback (most recent call last):
  File "/home/nandishms/test//src/scripts/ingestion/mysql_write.py", line 236, in write
    status=create(json_data, sessions, datafram, conn_details)
  File "/home/nandishms/test//src/scripts/ingestion/mysql_write.py", line 85, in create
    insert_data(json_data,conn_details,dataframe,conn)
  File "/home/nandishms/test//src/scripts/ingestion/mysql_write.py", line 76, in insert_data
    raise error
  File "/home/nandishms/test//src/scripts/ingestion/mysql_write.py", line 68, in insert_data
    dataframe.to_sql(target["table_name"], connection,
  File "/home/nandishms/.local/lib/python3.10/site-packages/pandas/core/generic.py", line 2878, in to_sql
    return sql.to_sql(
  File "/home/nandishms/.local/lib/python3.10/site-packages/pandas/io/sql.py", line 769, in to_sql
    return pandas_sql.to_sql(
  File "/home/nandishms/.local/lib/python3.10/site-packages/pandas/io/sql.py", line 1910, in to_sql
    table = self.prep_table(
  File "/home/nandishms/.local/lib/python3.10/site-packages/pandas/io/sql.py", line 1814, in prep_table
    table.create()
  File "/home/nandishms/.local/lib/python3.10/site-packages/pandas/io/sql.py", line 914, in create
    self._execute_create()
  File "/home/nandishms/.local/lib/python3.10/site-packages/pandas/io/sql.py", line 900, in _execute_create
    self.table.create(bind=self.pd_sql.con)
  File "/home/nandishms/.local/lib/python3.10/site-packages/sqlalchemy/sql/schema.py", line 1291, in create
    bind._run_ddl_visitor(ddl.SchemaGenerator, self, checkfirst=checkfirst)
  File "/home/nandishms/.local/lib/python3.10/site-packages/sqlalchemy/engine/base.py", line 2443, in _run_ddl_visitor
    visitorcallable(self.dialect, self, **kwargs).traverse_single(element)
  File "/home/nandishms/.local/lib/python3.10/site-packages/sqlalchemy/sql/visitors.py", line 670, in traverse_single
    return meth(obj, **kw)
  File "/home/nandishms/.local/lib/python3.10/site-packages/sqlalchemy/sql/ddl.py", line 960, in visit_table
    )._invoke_with(self.connection)
  File "/home/nandishms/.local/lib/python3.10/site-packages/sqlalchemy/sql/ddl.py", line 315, in _invoke_with
    return bind.execute(self)
  File "/home/nandishms/.local/lib/python3.10/site-packages/sqlalchemy/engine/base.py", line 1412, in execute
    return meth(
  File "/home/nandishms/.local/lib/python3.10/site-packages/sqlalchemy/sql/ddl.py", line 181, in _execute_on_connection
    return connection._execute_ddl(
  File "/home/nandishms/.local/lib/python3.10/site-packages/sqlalchemy/engine/base.py", line 1524, in _execute_ddl
    ret = self._execute_context(
  File "/home/nandishms/.local/lib/python3.10/site-packages/sqlalchemy/engine/base.py", line 1844, in _execute_context
    return self._exec_single_context(
  File "/home/nandishms/.local/lib/python3.10/site-packages/sqlalchemy/engine/base.py", line 1984, in _exec_single_context
    self._handle_dbapi_exception(
  File "/home/nandishms/.local/lib/python3.10/site-packages/sqlalchemy/engine/base.py", line 2339, in _handle_dbapi_exception
    raise sqlalchemy_exception.with_traceback(exc_info[2]) from e
  File "/home/nandishms/.local/lib/python3.10/site-packages/sqlalchemy/engine/base.py", line 1965, in _exec_single_context
    self.dialect.do_execute(
  File "/home/nandishms/.local/lib/python3.10/site-packages/sqlalchemy/engine/default.py", line 921, in do_execute
    cursor.execute(statement, parameters)
  File "/home/nandishms/.local/lib/python3.10/site-packages/pymysql/cursors.py", line 153, in execute
    result = self._query(query)
  File "/home/nandishms/.local/lib/python3.10/site-packages/pymysql/cursors.py", line 322, in _query
    conn.query(q)
  File "/home/nandishms/.local/lib/python3.10/site-packages/pymysql/connections.py", line 558, in query
    self._affected_rows = self._read_query_result(unbuffered=unbuffered)
  File "/home/nandishms/.local/lib/python3.10/site-packages/pymysql/connections.py", line 822, in _read_query_result
    result.read()
  File "/home/nandishms/.local/lib/python3.10/site-packages/pymysql/connections.py", line 1200, in read
    first_packet = self.connection._read_packet()
  File "/home/nandishms/.local/lib/python3.10/site-packages/pymysql/connections.py", line 772, in _read_packet
    packet.raise_for_error()
  File "/home/nandishms/.local/lib/python3.10/site-packages/pymysql/protocol.py", line 221, in raise_for_error
    err.raise_mysql_exception(self._data)
  File "/home/nandishms/.local/lib/python3.10/site-packages/pymysql/err.py", line 143, in raise_mysql_exception
    raise errorclass(errno, errval)
sqlalchemy.exc.ProgrammingError: (pymysql.err.ProgrammingError) (1064, "You have an error in your SQL syntax; check the manual that corresponds to your MySQL server version for the right syntax to use near ')' at line 2")
[SQL: 
CREATE TABLE rest_api_data19 (
)

]
(Background on this error at: https://sqlalche.me/e/20/f405)
2023-07-31 19:02:14,080 | task_logger | MainProcess  |        audit                  | INFO  | audit status code:200
2023-07-31 19:02:14,083 | task_logger | MainProcess  |        engine_main            | WARNING | rest_api_test got failed engine
2023-07-31 19:02:14,083 | task_logger | MainProcess  |        engine_main            | ERROR | error in  (pymysql.err.ProgrammingError) (1064, "You have an error in your SQL syntax; check the manual that corresponds to your MySQL server version for the right syntax to use near ')' at line 2")
[SQL: 
CREATE TABLE rest_api_data19 (
)

]
(Background on this error at: https://sqlalche.me/e/20/f405).
Traceback (most recent call last):
  File "/home/nandishms/.local/lib/python3.10/site-packages/sqlalchemy/engine/base.py", line 1965, in _exec_single_context
    self.dialect.do_execute(
  File "/home/nandishms/.local/lib/python3.10/site-packages/sqlalchemy/engine/default.py", line 921, in do_execute
    cursor.execute(statement, parameters)
  File "/home/nandishms/.local/lib/python3.10/site-packages/pymysql/cursors.py", line 153, in execute
    result = self._query(query)
  File "/home/nandishms/.local/lib/python3.10/site-packages/pymysql/cursors.py", line 322, in _query
    conn.query(q)
  File "/home/nandishms/.local/lib/python3.10/site-packages/pymysql/connections.py", line 558, in query
    self._affected_rows = self._read_query_result(unbuffered=unbuffered)
  File "/home/nandishms/.local/lib/python3.10/site-packages/pymysql/connections.py", line 822, in _read_query_result
    result.read()
  File "/home/nandishms/.local/lib/python3.10/site-packages/pymysql/connections.py", line 1200, in read
    first_packet = self.connection._read_packet()
  File "/home/nandishms/.local/lib/python3.10/site-packages/pymysql/connections.py", line 772, in _read_packet
    packet.raise_for_error()
  File "/home/nandishms/.local/lib/python3.10/site-packages/pymysql/protocol.py", line 221, in raise_for_error
    err.raise_mysql_exception(self._data)
  File "/home/nandishms/.local/lib/python3.10/site-packages/pymysql/err.py", line 143, in raise_mysql_exception
    raise errorclass(errno, errval)
pymysql.err.ProgrammingError: (1064, "You have an error in your SQL syntax; check the manual that corresponds to your MySQL server version for the right syntax to use near ')' at line 2")

The above exception was the direct cause of the following exception:

Traceback (most recent call last):
  File "/home/nandishms/test//src/scripts/engine_main/engine_code.py", line 373, in engine_main
    value=write(json_data, i,counter,config_file_path,task_id,run_id,
  File "/home/nandishms/test//src/scripts/ingestion/mysql_write.py", line 267, in write
    raise error
  File "/home/nandishms/test//src/scripts/ingestion/mysql_write.py", line 236, in write
    status=create(json_data, sessions, datafram, conn_details)
  File "/home/nandishms/test//src/scripts/ingestion/mysql_write.py", line 85, in create
    insert_data(json_data,conn_details,dataframe,conn)
  File "/home/nandishms/test//src/scripts/ingestion/mysql_write.py", line 76, in insert_data
    raise error
  File "/home/nandishms/test//src/scripts/ingestion/mysql_write.py", line 68, in insert_data
    dataframe.to_sql(target["table_name"], connection,
  File "/home/nandishms/.local/lib/python3.10/site-packages/pandas/core/generic.py", line 2878, in to_sql
    return sql.to_sql(
  File "/home/nandishms/.local/lib/python3.10/site-packages/pandas/io/sql.py", line 769, in to_sql
    return pandas_sql.to_sql(
  File "/home/nandishms/.local/lib/python3.10/site-packages/pandas/io/sql.py", line 1910, in to_sql
    table = self.prep_table(
  File "/home/nandishms/.local/lib/python3.10/site-packages/pandas/io/sql.py", line 1814, in prep_table
    table.create()
  File "/home/nandishms/.local/lib/python3.10/site-packages/pandas/io/sql.py", line 914, in create
    self._execute_create()
  File "/home/nandishms/.local/lib/python3.10/site-packages/pandas/io/sql.py", line 900, in _execute_create
    self.table.create(bind=self.pd_sql.con)
  File "/home/nandishms/.local/lib/python3.10/site-packages/sqlalchemy/sql/schema.py", line 1291, in create
    bind._run_ddl_visitor(ddl.SchemaGenerator, self, checkfirst=checkfirst)
  File "/home/nandishms/.local/lib/python3.10/site-packages/sqlalchemy/engine/base.py", line 2443, in _run_ddl_visitor
    visitorcallable(self.dialect, self, **kwargs).traverse_single(element)
  File "/home/nandishms/.local/lib/python3.10/site-packages/sqlalchemy/sql/visitors.py", line 670, in traverse_single
    return meth(obj, **kw)
  File "/home/nandishms/.local/lib/python3.10/site-packages/sqlalchemy/sql/ddl.py", line 960, in visit_table
    )._invoke_with(self.connection)
  File "/home/nandishms/.local/lib/python3.10/site-packages/sqlalchemy/sql/ddl.py", line 315, in _invoke_with
    return bind.execute(self)
  File "/home/nandishms/.local/lib/python3.10/site-packages/sqlalchemy/engine/base.py", line 1412, in execute
    return meth(
  File "/home/nandishms/.local/lib/python3.10/site-packages/sqlalchemy/sql/ddl.py", line 181, in _execute_on_connection
    return connection._execute_ddl(
  File "/home/nandishms/.local/lib/python3.10/site-packages/sqlalchemy/engine/base.py", line 1524, in _execute_ddl
    ret = self._execute_context(
  File "/home/nandishms/.local/lib/python3.10/site-packages/sqlalchemy/engine/base.py", line 1844, in _execute_context
    return self._exec_single_context(
  File "/home/nandishms/.local/lib/python3.10/site-packages/sqlalchemy/engine/base.py", line 1984, in _exec_single_context
    self._handle_dbapi_exception(
  File "/home/nandishms/.local/lib/python3.10/site-packages/sqlalchemy/engine/base.py", line 2339, in _handle_dbapi_exception
    raise sqlalchemy_exception.with_traceback(exc_info[2]) from e
  File "/home/nandishms/.local/lib/python3.10/site-packages/sqlalchemy/engine/base.py", line 1965, in _exec_single_context
    self.dialect.do_execute(
  File "/home/nandishms/.local/lib/python3.10/site-packages/sqlalchemy/engine/default.py", line 921, in do_execute
    cursor.execute(statement, parameters)
  File "/home/nandishms/.local/lib/python3.10/site-packages/pymysql/cursors.py", line 153, in execute
    result = self._query(query)
  File "/home/nandishms/.local/lib/python3.10/site-packages/pymysql/cursors.py", line 322, in _query
    conn.query(q)
  File "/home/nandishms/.local/lib/python3.10/site-packages/pymysql/connections.py", line 558, in query
    self._affected_rows = self._read_query_result(unbuffered=unbuffered)
  File "/home/nandishms/.local/lib/python3.10/site-packages/pymysql/connections.py", line 822, in _read_query_result
    result.read()
  File "/home/nandishms/.local/lib/python3.10/site-packages/pymysql/connections.py", line 1200, in read
    first_packet = self.connection._read_packet()
  File "/home/nandishms/.local/lib/python3.10/site-packages/pymysql/connections.py", line 772, in _read_packet
    packet.raise_for_error()
  File "/home/nandishms/.local/lib/python3.10/site-packages/pymysql/protocol.py", line 221, in raise_for_error
    err.raise_mysql_exception(self._data)
  File "/home/nandishms/.local/lib/python3.10/site-packages/pymysql/err.py", line 143, in raise_mysql_exception
    raise errorclass(errno, errval)
sqlalchemy.exc.ProgrammingError: (pymysql.err.ProgrammingError) (1064, "You have an error in your SQL syntax; check the manual that corresponds to your MySQL server version for the right syntax to use near ')' at line 2")
[SQL: 
CREATE TABLE rest_api_data19 (
)

]
(Background on this error at: https://sqlalche.me/e/20/f405)
2023-07-31 19:02:14,084 | task_logger | MainProcess  |        execute_engine         | ERROR | error in executing engine (pymysql.err.ProgrammingError) (1064, "You have an error in your SQL syntax; check the manual that corresponds to your MySQL server version for the right syntax to use near ')' at line 2")
[SQL: 
CREATE TABLE rest_api_data19 (
)

]
(Background on this error at: https://sqlalche.me/e/20/f405).
Traceback (most recent call last):
  File "/home/nandishms/.local/lib/python3.10/site-packages/sqlalchemy/engine/base.py", line 1965, in _exec_single_context
    self.dialect.do_execute(
  File "/home/nandishms/.local/lib/python3.10/site-packages/sqlalchemy/engine/default.py", line 921, in do_execute
    cursor.execute(statement, parameters)
  File "/home/nandishms/.local/lib/python3.10/site-packages/pymysql/cursors.py", line 153, in execute
    result = self._query(query)
  File "/home/nandishms/.local/lib/python3.10/site-packages/pymysql/cursors.py", line 322, in _query
    conn.query(q)
  File "/home/nandishms/.local/lib/python3.10/site-packages/pymysql/connections.py", line 558, in query
    self._affected_rows = self._read_query_result(unbuffered=unbuffered)
  File "/home/nandishms/.local/lib/python3.10/site-packages/pymysql/connections.py", line 822, in _read_query_result
    result.read()
  File "/home/nandishms/.local/lib/python3.10/site-packages/pymysql/connections.py", line 1200, in read
    first_packet = self.connection._read_packet()
  File "/home/nandishms/.local/lib/python3.10/site-packages/pymysql/connections.py", line 772, in _read_packet
    packet.raise_for_error()
  File "/home/nandishms/.local/lib/python3.10/site-packages/pymysql/protocol.py", line 221, in raise_for_error
    err.raise_mysql_exception(self._data)
  File "/home/nandishms/.local/lib/python3.10/site-packages/pymysql/err.py", line 143, in raise_mysql_exception
    raise errorclass(errno, errval)
pymysql.err.ProgrammingError: (1064, "You have an error in your SQL syntax; check the manual that corresponds to your MySQL server version for the right syntax to use near ')' at line 2")

The above exception was the direct cause of the following exception:

Traceback (most recent call last):
  File "/home/nandishms/test/download.py", line 263, in execute_engine
    engine_code.engine_main(prj_nm,task_name,config_path,run_id,file_path,iter_value)
  File "/home/nandishms/test//src/scripts/engine_main/engine_code.py", line 476, in engine_main
    raise error
  File "/home/nandishms/test//src/scripts/engine_main/engine_code.py", line 373, in engine_main
    value=write(json_data, i,counter,config_file_path,task_id,run_id,
  File "/home/nandishms/test//src/scripts/ingestion/mysql_write.py", line 267, in write
    raise error
  File "/home/nandishms/test//src/scripts/ingestion/mysql_write.py", line 236, in write
    status=create(json_data, sessions, datafram, conn_details)
  File "/home/nandishms/test//src/scripts/ingestion/mysql_write.py", line 85, in create
    insert_data(json_data,conn_details,dataframe,conn)
  File "/home/nandishms/test//src/scripts/ingestion/mysql_write.py", line 76, in insert_data
    raise error
  File "/home/nandishms/test//src/scripts/ingestion/mysql_write.py", line 68, in insert_data
    dataframe.to_sql(target["table_name"], connection,
  File "/home/nandishms/.local/lib/python3.10/site-packages/pandas/core/generic.py", line 2878, in to_sql
    return sql.to_sql(
  File "/home/nandishms/.local/lib/python3.10/site-packages/pandas/io/sql.py", line 769, in to_sql
    return pandas_sql.to_sql(
  File "/home/nandishms/.local/lib/python3.10/site-packages/pandas/io/sql.py", line 1910, in to_sql
    table = self.prep_table(
  File "/home/nandishms/.local/lib/python3.10/site-packages/pandas/io/sql.py", line 1814, in prep_table
    table.create()
  File "/home/nandishms/.local/lib/python3.10/site-packages/pandas/io/sql.py", line 914, in create
    self._execute_create()
  File "/home/nandishms/.local/lib/python3.10/site-packages/pandas/io/sql.py", line 900, in _execute_create
    self.table.create(bind=self.pd_sql.con)
  File "/home/nandishms/.local/lib/python3.10/site-packages/sqlalchemy/sql/schema.py", line 1291, in create
    bind._run_ddl_visitor(ddl.SchemaGenerator, self, checkfirst=checkfirst)
  File "/home/nandishms/.local/lib/python3.10/site-packages/sqlalchemy/engine/base.py", line 2443, in _run_ddl_visitor
    visitorcallable(self.dialect, self, **kwargs).traverse_single(element)
  File "/home/nandishms/.local/lib/python3.10/site-packages/sqlalchemy/sql/visitors.py", line 670, in traverse_single
    return meth(obj, **kw)
  File "/home/nandishms/.local/lib/python3.10/site-packages/sqlalchemy/sql/ddl.py", line 960, in visit_table
    )._invoke_with(self.connection)
  File "/home/nandishms/.local/lib/python3.10/site-packages/sqlalchemy/sql/ddl.py", line 315, in _invoke_with
    return bind.execute(self)
  File "/home/nandishms/.local/lib/python3.10/site-packages/sqlalchemy/engine/base.py", line 1412, in execute
    return meth(
  File "/home/nandishms/.local/lib/python3.10/site-packages/sqlalchemy/sql/ddl.py", line 181, in _execute_on_connection
    return connection._execute_ddl(
  File "/home/nandishms/.local/lib/python3.10/site-packages/sqlalchemy/engine/base.py", line 1524, in _execute_ddl
    ret = self._execute_context(
  File "/home/nandishms/.local/lib/python3.10/site-packages/sqlalchemy/engine/base.py", line 1844, in _execute_context
    return self._exec_single_context(
  File "/home/nandishms/.local/lib/python3.10/site-packages/sqlalchemy/engine/base.py", line 1984, in _exec_single_context
    self._handle_dbapi_exception(
  File "/home/nandishms/.local/lib/python3.10/site-packages/sqlalchemy/engine/base.py", line 2339, in _handle_dbapi_exception
    raise sqlalchemy_exception.with_traceback(exc_info[2]) from e
  File "/home/nandishms/.local/lib/python3.10/site-packages/sqlalchemy/engine/base.py", line 1965, in _exec_single_context
    self.dialect.do_execute(
  File "/home/nandishms/.local/lib/python3.10/site-packages/sqlalchemy/engine/default.py", line 921, in do_execute
    cursor.execute(statement, parameters)
  File "/home/nandishms/.local/lib/python3.10/site-packages/pymysql/cursors.py", line 153, in execute
    result = self._query(query)
  File "/home/nandishms/.local/lib/python3.10/site-packages/pymysql/cursors.py", line 322, in _query
    conn.query(q)
  File "/home/nandishms/.local/lib/python3.10/site-packages/pymysql/connections.py", line 558, in query
    self._affected_rows = self._read_query_result(unbuffered=unbuffered)
  File "/home/nandishms/.local/lib/python3.10/site-packages/pymysql/connections.py", line 822, in _read_query_result
    result.read()
  File "/home/nandishms/.local/lib/python3.10/site-packages/pymysql/connections.py", line 1200, in read
    first_packet = self.connection._read_packet()
  File "/home/nandishms/.local/lib/python3.10/site-packages/pymysql/connections.py", line 772, in _read_packet
    packet.raise_for_error()
  File "/home/nandishms/.local/lib/python3.10/site-packages/pymysql/protocol.py", line 221, in raise_for_error
    err.raise_mysql_exception(self._data)
  File "/home/nandishms/.local/lib/python3.10/site-packages/pymysql/err.py", line 143, in raise_mysql_exception
    raise errorclass(errno, errval)
sqlalchemy.exc.ProgrammingError: (pymysql.err.ProgrammingError) (1064, "You have an error in your SQL syntax; check the manual that corresponds to your MySQL server version for the right syntax to use near ')' at line 2")
[SQL: 
CREATE TABLE rest_api_data19 (
)

]
(Background on this error at: https://sqlalche.me/e/20/f405)
