2023-07-31 19:02:02,000 | main_logger | MainProcess  |        <module>               | INFO  | Master execution started
2023-07-31 19:02:02,001 | main_logger | MainProcess  |        execute_pipeline_download | INFO  | calling the create_folder_structure function
2023-07-31 19:02:02,002 | main_logger | MainProcess  |        execute_pipeline_download | INFO  | calling the common_files_downloads function
2023-07-31 19:02:03,217 | main_logger | MainProcess  |        execute_pipeline_download | INFO  | calling the orchestrate_calling function
2023-07-31 19:02:03,219 | main_logger | MainProcess  |        task_orc_execution     | INFO  | execution at task level
2023-07-31 19:02:06,639 | main_logger | MainProcess  |        send_mail              | INFO  | mail sent
2023-07-31 19:02:14,086 | main_logger | MainProcess  |        task_orc_execution     | ERROR | error in orchestrate_task_calling (pymysql.err.ProgrammingError) (1064, "You have an error in your SQL syntax; check the manual that corresponds to your MySQL server version for the right syntax to use near ')' at line 2")
[SQL: 
CREATE TABLE rest_api_data19 (
)

]
(Background on this error at: https://sqlalche.me/e/20/f405).
Traceback (most recent call last):
  File "/home/nandishms/.local/lib/python3.10/site-packages/sqlalchemy/engine/base.py", line 1965, in _exec_single_context
    self.dialect.do_execute(
  File "/home/nandishms/.local/lib/python3.10/site-packages/sqlalchemy/engine/default.py", line 921, in do_execute
    cursor.execute(statement, parameters)
  File "/home/nandishms/.local/lib/python3.10/site-packages/pymysql/cursors.py", line 153, in execute
    result = self._query(query)
  File "/home/nandishms/.local/lib/python3.10/site-packages/pymysql/cursors.py", line 322, in _query
    conn.query(q)
  File "/home/nandishms/.local/lib/python3.10/site-packages/pymysql/connections.py", line 558, in query
    self._affected_rows = self._read_query_result(unbuffered=unbuffered)
  File "/home/nandishms/.local/lib/python3.10/site-packages/pymysql/connections.py", line 822, in _read_query_result
    result.read()
  File "/home/nandishms/.local/lib/python3.10/site-packages/pymysql/connections.py", line 1200, in read
    first_packet = self.connection._read_packet()
  File "/home/nandishms/.local/lib/python3.10/site-packages/pymysql/connections.py", line 772, in _read_packet
    packet.raise_for_error()
  File "/home/nandishms/.local/lib/python3.10/site-packages/pymysql/protocol.py", line 221, in raise_for_error
    err.raise_mysql_exception(self._data)
  File "/home/nandishms/.local/lib/python3.10/site-packages/pymysql/err.py", line 143, in raise_mysql_exception
    raise errorclass(errno, errval)
pymysql.err.ProgrammingError: (1064, "You have an error in your SQL syntax; check the manual that corresponds to your MySQL server version for the right syntax to use near ')' at line 2")

The above exception was the direct cause of the following exception:

Traceback (most recent call last):
  File "/home/nandishms/test/src/scripts/orchestration/orchestrate.py", line 608, in task_orc_execution
    execute_job(prj_nm,paths_data,task_nm,run_id,file_path,iter_value)
  File "/home/nandishms/test/src/scripts/orchestration/orchestrate.py", line 38, in execute_job
    raise error
  File "/home/nandishms/test/src/scripts/orchestration/orchestrate.py", line 35, in execute_job
    download.execute_engine(prj_nm,task_id,paths_data,run_id,file_path,iter_value)
  File "/home/nandishms/test/download.py", line 267, in execute_engine
    raise error
  File "/home/nandishms/test/download.py", line 263, in execute_engine
    engine_code.engine_main(prj_nm,task_name,config_path,run_id,file_path,iter_value)
  File "/home/nandishms/test//src/scripts/engine_main/engine_code.py", line 476, in engine_main
    raise error
  File "/home/nandishms/test//src/scripts/engine_main/engine_code.py", line 373, in engine_main
    value=write(json_data, i,counter,config_file_path,task_id,run_id,
  File "/home/nandishms/test//src/scripts/ingestion/mysql_write.py", line 267, in write
    raise error
  File "/home/nandishms/test//src/scripts/ingestion/mysql_write.py", line 236, in write
    status=create(json_data, sessions, datafram, conn_details)
  File "/home/nandishms/test//src/scripts/ingestion/mysql_write.py", line 85, in create
    insert_data(json_data,conn_details,dataframe,conn)
  File "/home/nandishms/test//src/scripts/ingestion/mysql_write.py", line 76, in insert_data
    raise error
  File "/home/nandishms/test//src/scripts/ingestion/mysql_write.py", line 68, in insert_data
    dataframe.to_sql(target["table_name"], connection,
  File "/home/nandishms/.local/lib/python3.10/site-packages/pandas/core/generic.py", line 2878, in to_sql
    return sql.to_sql(
  File "/home/nandishms/.local/lib/python3.10/site-packages/pandas/io/sql.py", line 769, in to_sql
    return pandas_sql.to_sql(
  File "/home/nandishms/.local/lib/python3.10/site-packages/pandas/io/sql.py", line 1910, in to_sql
    table = self.prep_table(
  File "/home/nandishms/.local/lib/python3.10/site-packages/pandas/io/sql.py", line 1814, in prep_table
    table.create()
  File "/home/nandishms/.local/lib/python3.10/site-packages/pandas/io/sql.py", line 914, in create
    self._execute_create()
  File "/home/nandishms/.local/lib/python3.10/site-packages/pandas/io/sql.py", line 900, in _execute_create
    self.table.create(bind=self.pd_sql.con)
  File "/home/nandishms/.local/lib/python3.10/site-packages/sqlalchemy/sql/schema.py", line 1291, in create
    bind._run_ddl_visitor(ddl.SchemaGenerator, self, checkfirst=checkfirst)
  File "/home/nandishms/.local/lib/python3.10/site-packages/sqlalchemy/engine/base.py", line 2443, in _run_ddl_visitor
    visitorcallable(self.dialect, self, **kwargs).traverse_single(element)
  File "/home/nandishms/.local/lib/python3.10/site-packages/sqlalchemy/sql/visitors.py", line 670, in traverse_single
    return meth(obj, **kw)
  File "/home/nandishms/.local/lib/python3.10/site-packages/sqlalchemy/sql/ddl.py", line 960, in visit_table
    )._invoke_with(self.connection)
  File "/home/nandishms/.local/lib/python3.10/site-packages/sqlalchemy/sql/ddl.py", line 315, in _invoke_with
    return bind.execute(self)
  File "/home/nandishms/.local/lib/python3.10/site-packages/sqlalchemy/engine/base.py", line 1412, in execute
    return meth(
  File "/home/nandishms/.local/lib/python3.10/site-packages/sqlalchemy/sql/ddl.py", line 181, in _execute_on_connection
    return connection._execute_ddl(
  File "/home/nandishms/.local/lib/python3.10/site-packages/sqlalchemy/engine/base.py", line 1524, in _execute_ddl
    ret = self._execute_context(
  File "/home/nandishms/.local/lib/python3.10/site-packages/sqlalchemy/engine/base.py", line 1844, in _execute_context
    return self._exec_single_context(
  File "/home/nandishms/.local/lib/python3.10/site-packages/sqlalchemy/engine/base.py", line 1984, in _exec_single_context
    self._handle_dbapi_exception(
  File "/home/nandishms/.local/lib/python3.10/site-packages/sqlalchemy/engine/base.py", line 2339, in _handle_dbapi_exception
    raise sqlalchemy_exception.with_traceback(exc_info[2]) from e
  File "/home/nandishms/.local/lib/python3.10/site-packages/sqlalchemy/engine/base.py", line 1965, in _exec_single_context
    self.dialect.do_execute(
  File "/home/nandishms/.local/lib/python3.10/site-packages/sqlalchemy/engine/default.py", line 921, in do_execute
    cursor.execute(statement, parameters)
  File "/home/nandishms/.local/lib/python3.10/site-packages/pymysql/cursors.py", line 153, in execute
    result = self._query(query)
  File "/home/nandishms/.local/lib/python3.10/site-packages/pymysql/cursors.py", line 322, in _query
    conn.query(q)
  File "/home/nandishms/.local/lib/python3.10/site-packages/pymysql/connections.py", line 558, in query
    self._affected_rows = self._read_query_result(unbuffered=unbuffered)
  File "/home/nandishms/.local/lib/python3.10/site-packages/pymysql/connections.py", line 822, in _read_query_result
    result.read()
  File "/home/nandishms/.local/lib/python3.10/site-packages/pymysql/connections.py", line 1200, in read
    first_packet = self.connection._read_packet()
  File "/home/nandishms/.local/lib/python3.10/site-packages/pymysql/connections.py", line 772, in _read_packet
    packet.raise_for_error()
  File "/home/nandishms/.local/lib/python3.10/site-packages/pymysql/protocol.py", line 221, in raise_for_error
    err.raise_mysql_exception(self._data)
  File "/home/nandishms/.local/lib/python3.10/site-packages/pymysql/err.py", line 143, in raise_mysql_exception
    raise errorclass(errno, errval)
sqlalchemy.exc.ProgrammingError: (pymysql.err.ProgrammingError) (1064, "You have an error in your SQL syntax; check the manual that corresponds to your MySQL server version for the right syntax to use near ')' at line 2")
[SQL: 
CREATE TABLE rest_api_data19 (
)

]
(Background on this error at: https://sqlalche.me/e/20/f405)
2023-07-31 19:02:14,089 | main_logger | MainProcess  |        get_ind_task_status    | INFO  | rest_api_test task is FAILED
2023-07-31 19:02:14,090 | main_logger | MainProcess  |        task_orc_execution     | INFO  | Task rest_api_test Execution failed.
2023-07-31 19:02:18,004 | main_logger | MainProcess  |        send_mail              | INFO  | mail sent
